{
 "cells": [
  {
   "cell_type": "code",
   "execution_count": 13,
   "metadata": {},
   "outputs": [
    {
     "name": "stdout",
     "output_type": "stream",
     "text": [
      "The autoreload extension is already loaded. To reload it, use:\n",
      "  %reload_ext autoreload\n"
     ]
    }
   ],
   "source": [
    "%load_ext autoreload\n",
    "%autoreload 2"
   ]
  },
  {
   "cell_type": "code",
   "execution_count": 14,
   "metadata": {},
   "outputs": [],
   "source": [
    "import pandas as pd\n",
    "from functions import main_cleaning\n",
    "\n",
    "pd.set_option('display.max_columns', None) \n",
    "\n",
    "df_raw = pd.read_csv(\"dielectron.csv\")"
   ]
  },
  {
   "cell_type": "code",
   "execution_count": 15,
   "metadata": {},
   "outputs": [
    {
     "name": "stderr",
     "output_type": "stream",
     "text": [
      "e:\\Iván\\Documentos\\Clase\\Informatica\\Beca IronHack\\Temario\\PROYECTOS\\Proyecto_final_1710\\functions.py:12: SettingWithCopyWarning: \n",
      "A value is trying to be set on a copy of a slice from a DataFrame.\n",
      "Try using .loc[row_indexer,col_indexer] = value instead\n",
      "\n",
      "See the caveats in the documentation: https://pandas.pydata.org/pandas-docs/stable/user_guide/indexing.html#returning-a-view-versus-a-copy\n",
      "  df[\"is_same_charge\"] = df[\"Q1\"] == df[\"Q2\"]\n",
      "e:\\Iván\\Documentos\\Clase\\Informatica\\Beca IronHack\\Temario\\PROYECTOS\\Proyecto_final_1710\\functions.py:19: SettingWithCopyWarning: \n",
      "A value is trying to be set on a copy of a slice from a DataFrame.\n",
      "Try using .loc[row_indexer,col_indexer] = value instead\n",
      "\n",
      "See the caveats in the documentation: https://pandas.pydata.org/pandas-docs/stable/user_guide/indexing.html#returning-a-view-versus-a-copy\n",
      "  df[\"is_outlier\"] = False\n"
     ]
    }
   ],
   "source": [
    "df_cleaned = main_cleaning(df_raw)\n",
    "df_cleaned.reset_index(drop=True, inplace=True)"
   ]
  },
  {
   "cell_type": "markdown",
   "metadata": {},
   "source": [
    "# MACHINE LEARNING"
   ]
  },
  {
   "cell_type": "code",
   "execution_count": 16,
   "metadata": {},
   "outputs": [],
   "source": [
    "df_ml = df_cleaned.dropna()"
   ]
  },
  {
   "cell_type": "code",
   "execution_count": 17,
   "metadata": {},
   "outputs": [
    {
     "name": "stdout",
     "output_type": "stream",
     "text": [
      "TensorFlow version: 2.17.0\n"
     ]
    }
   ],
   "source": [
    "import tensorflow as tf\n",
    "\n",
    "print(\"TensorFlow version:\", tf.__version__)"
   ]
  },
  {
   "cell_type": "code",
   "execution_count": 18,
   "metadata": {},
   "outputs": [],
   "source": [
    "from sklearn.ensemble import RandomForestRegressor\n",
    "from sklearn.preprocessing import StandardScaler\n",
    "from sklearn.neighbors import KNeighborsRegressor\n",
    "from sklearn.linear_model import LinearRegression\n",
    "from sklearn.tree import DecisionTreeRegressor\n",
    "from sklearn.svm import SVR\n",
    "from sklearn.metrics import root_mean_squared_error, mean_absolute_error, r2_score"
   ]
  },
  {
   "cell_type": "code",
   "execution_count": 19,
   "metadata": {},
   "outputs": [],
   "source": [
    "features_lower = df_ml[[\"Run\", \"pz1\", \"pz2\", \"is_same_charge\", \"is_outlier\"]]\n",
    "target_lower = df_ml[[\"M\"]]"
   ]
  },
  {
   "cell_type": "code",
   "execution_count": 20,
   "metadata": {},
   "outputs": [],
   "source": [
    "from sklearn.model_selection import train_test_split\n",
    "\n",
    "X_train_lower, X_test_lower, y_train_lower, y_test_lower = train_test_split(features_lower, target_lower, test_size=0.20, random_state=42)"
   ]
  },
  {
   "cell_type": "code",
   "execution_count": 21,
   "metadata": {},
   "outputs": [],
   "source": [
    "x_train, x_test = X_train_lower / 255.0, X_test_lower / 255.0"
   ]
  },
  {
   "cell_type": "code",
   "execution_count": 22,
   "metadata": {},
   "outputs": [
    {
     "name": "stderr",
     "output_type": "stream",
     "text": [
      "c:\\Anaconda\\Lib\\site-packages\\keras\\src\\layers\\reshaping\\flatten.py:37: UserWarning: Do not pass an `input_shape`/`input_dim` argument to a layer. When using Sequential models, prefer using an `Input(shape)` object as the first layer in the model instead.\n",
      "  super().__init__(**kwargs)\n"
     ]
    }
   ],
   "source": [
    "model = tf.keras.models.Sequential([\n",
    "  tf.keras.layers.Flatten(input_shape=(28, 28)),\n",
    "  tf.keras.layers.Dense(128, activation='relu'),\n",
    "  tf.keras.layers.Dropout(0.2),\n",
    "  tf.keras.layers.Dense(10)\n",
    "])"
   ]
  },
  {
   "cell_type": "code",
   "execution_count": 23,
   "metadata": {},
   "outputs": [
    {
     "ename": "ValueError",
     "evalue": "Exception encountered when calling Sequential.call().\n\n\u001b[1mInvalid input shape for input [[ 5.7691766e+02 -3.3877607e-02 -2.6629138e-01  0.0000000e+00\n   0.0000000e+00]]. Expected shape (None, 28, 28), but input has incompatible shape (1, 5)\u001b[0m\n\nArguments received by Sequential.call():\n  • inputs=tf.Tensor(shape=(1, 5), dtype=float32)\n  • training=None\n  • mask=None",
     "output_type": "error",
     "traceback": [
      "\u001b[1;31m---------------------------------------------------------------------------\u001b[0m",
      "\u001b[1;31mValueError\u001b[0m                                Traceback (most recent call last)",
      "Cell \u001b[1;32mIn[23], line 1\u001b[0m\n\u001b[1;32m----> 1\u001b[0m predictions \u001b[38;5;241m=\u001b[39m model(x_train[:\u001b[38;5;241m1\u001b[39m])\u001b[38;5;241m.\u001b[39mnumpy()\n\u001b[0;32m      2\u001b[0m predictions\n",
      "File \u001b[1;32mc:\\Anaconda\\Lib\\site-packages\\keras\\src\\utils\\traceback_utils.py:122\u001b[0m, in \u001b[0;36mfilter_traceback.<locals>.error_handler\u001b[1;34m(*args, **kwargs)\u001b[0m\n\u001b[0;32m    119\u001b[0m     filtered_tb \u001b[38;5;241m=\u001b[39m _process_traceback_frames(e\u001b[38;5;241m.\u001b[39m__traceback__)\n\u001b[0;32m    120\u001b[0m     \u001b[38;5;66;03m# To get the full stack trace, call:\u001b[39;00m\n\u001b[0;32m    121\u001b[0m     \u001b[38;5;66;03m# `keras.config.disable_traceback_filtering()`\u001b[39;00m\n\u001b[1;32m--> 122\u001b[0m     \u001b[38;5;28;01mraise\u001b[39;00m e\u001b[38;5;241m.\u001b[39mwith_traceback(filtered_tb) \u001b[38;5;28;01mfrom\u001b[39;00m \u001b[38;5;28;01mNone\u001b[39;00m\n\u001b[0;32m    123\u001b[0m \u001b[38;5;28;01mfinally\u001b[39;00m:\n\u001b[0;32m    124\u001b[0m     \u001b[38;5;28;01mdel\u001b[39;00m filtered_tb\n",
      "File \u001b[1;32mc:\\Anaconda\\Lib\\site-packages\\keras\\src\\models\\functional.py:264\u001b[0m, in \u001b[0;36mFunctional._adjust_input_rank\u001b[1;34m(self, flat_inputs)\u001b[0m\n\u001b[0;32m    262\u001b[0m             adjusted\u001b[38;5;241m.\u001b[39mappend(ops\u001b[38;5;241m.\u001b[39mexpand_dims(x, axis\u001b[38;5;241m=\u001b[39m\u001b[38;5;241m-\u001b[39m\u001b[38;5;241m1\u001b[39m))\n\u001b[0;32m    263\u001b[0m             \u001b[38;5;28;01mcontinue\u001b[39;00m\n\u001b[1;32m--> 264\u001b[0m     \u001b[38;5;28;01mraise\u001b[39;00m \u001b[38;5;167;01mValueError\u001b[39;00m(\n\u001b[0;32m    265\u001b[0m         \u001b[38;5;124mf\u001b[39m\u001b[38;5;124m\"\u001b[39m\u001b[38;5;124mInvalid input shape for input \u001b[39m\u001b[38;5;132;01m{\u001b[39;00mx\u001b[38;5;132;01m}\u001b[39;00m\u001b[38;5;124m. Expected shape \u001b[39m\u001b[38;5;124m\"\u001b[39m\n\u001b[0;32m    266\u001b[0m         \u001b[38;5;124mf\u001b[39m\u001b[38;5;124m\"\u001b[39m\u001b[38;5;132;01m{\u001b[39;00mref_shape\u001b[38;5;132;01m}\u001b[39;00m\u001b[38;5;124m, but input has incompatible shape \u001b[39m\u001b[38;5;132;01m{\u001b[39;00mx\u001b[38;5;241m.\u001b[39mshape\u001b[38;5;132;01m}\u001b[39;00m\u001b[38;5;124m\"\u001b[39m\n\u001b[0;32m    267\u001b[0m     )\n\u001b[0;32m    268\u001b[0m \u001b[38;5;66;03m# Add back metadata.\u001b[39;00m\n\u001b[0;32m    269\u001b[0m \u001b[38;5;28;01mfor\u001b[39;00m i \u001b[38;5;129;01min\u001b[39;00m \u001b[38;5;28mrange\u001b[39m(\u001b[38;5;28mlen\u001b[39m(flat_inputs)):\n",
      "\u001b[1;31mValueError\u001b[0m: Exception encountered when calling Sequential.call().\n\n\u001b[1mInvalid input shape for input [[ 5.7691766e+02 -3.3877607e-02 -2.6629138e-01  0.0000000e+00\n   0.0000000e+00]]. Expected shape (None, 28, 28), but input has incompatible shape (1, 5)\u001b[0m\n\nArguments received by Sequential.call():\n  • inputs=tf.Tensor(shape=(1, 5), dtype=float32)\n  • training=None\n  • mask=None"
     ]
    }
   ],
   "source": [
    "predictions = model(x_train[:1]).numpy()\n",
    "predictions"
   ]
  },
  {
   "cell_type": "code",
   "execution_count": null,
   "metadata": {},
   "outputs": [],
   "source": [
    "tf.nn.softmax(predictions).numpy()"
   ]
  }
 ],
 "metadata": {
  "kernelspec": {
   "display_name": "base",
   "language": "python",
   "name": "python3"
  },
  "language_info": {
   "codemirror_mode": {
    "name": "ipython",
    "version": 3
   },
   "file_extension": ".py",
   "mimetype": "text/x-python",
   "name": "python",
   "nbconvert_exporter": "python",
   "pygments_lexer": "ipython3",
   "version": "3.12.4"
  }
 },
 "nbformat": 4,
 "nbformat_minor": 2
}
